<?xml version="1.0" ?>
<!-- =================================================================================== -->
<!-- |    This document was autogenerated by xacro from Hunker.urdf.xacro              | -->
<!-- |    EDITING THIS FILE BY HAND IS NOT RECOMMENDED                                 | -->
<!-- =================================================================================== -->
<!-- +X/L is forward, +Y/W is left, +Z/H is up -->
<robot name="Hunker" xmlns:xacro="http://www.ros.org/wiki/xacro">
  <link name="base_link">
    <visual>
      <geometry>
        <box size="0.3 0.3 0.03"/>
      </geometry>
      <origin xyz="0.0 0.0 0.015"/>
      <material name="blue">
        <color rgba="0.125 0.125 1.0 1.0"/>
      </material>
    </visual>
    <visual>
      <geometry>
        <box size="0.3 0.3 0.03"/>
      </geometry>
      <origin xyz="0.0 0.0 0.285"/>
      <material name="blue">
        <color rgba="0.125 0.125 1.0 1.0"/>
      </material>
    </visual>
    <visual>
      <geometry>
        <box size="0.36 0.24 0.24"/>
      </geometry>
      <origin xyz="-0.27 0.0 0.15"/>
      <material name="translucent">
        <color rgba="0.5 0.5 0.5 1.0"/>
      </material>
    </visual>
    <visual>
      <geometry>
        <box size="0.24 0.36 0.24"/>
      </geometry>
      <origin xyz="0.0 0.27 0.15"/>
      <material name="translucent">
        <color rgba="0.5 0.5 0.5 1.0"/>
      </material>
    </visual>
    <visual>
      <geometry>
        <box size="0.24 0.36 0.24"/>
      </geometry>
      <origin xyz="0.0 -0.27 0.15"/>
      <material name="translucent">
        <color rgba="0.5 0.5 0.5 1.0"/>
      </material>
    </visual>
    <visual>
      <geometry>
        <box size="0.36 0.24 0.24"/>
      </geometry>
      <origin xyz="0.27 0.0 0.15"/>
      <material name="translucent">
        <color rgba="0.5 0.5 0.5 1.0"/>
      </material>
    </visual>
  </link>
  <link name="backRightHip">
    <visual>
      <geometry>
        <cylinder length="0.03" radius="0.09"/>
      </geometry>
      <origin xyz="0.0 0.0 0.015"/>
      <material name="black">
        <color rgba="0.125 0.125 0.125 1.0"/>
      </material>
    </visual>
    <visual>
      <geometry>
        <box size="0.42 0.18 0.03"/>
      </geometry>
      <origin xyz="-0.18 0.0 0.045"/>
      <material name="mud">
        <color rgba="0.5 0.5 0.0 1.0"/>
      </material>
    </visual>
    <visual>
      <geometry>
        <box size="0.3 0.18 0.03"/>
      </geometry>
      <origin xyz="-0.24 0.0 0.015"/>
      <material name="mud">
        <color rgba="0.5 0.5 0.0 1.0"/>
      </material>
    </visual>
    <visual>
      <geometry>
        <box size="0.42 0.06 0.03"/>
      </geometry>
      <origin xyz="-0.18 0.0 -0.255"/>
      <material name="mud">
        <color rgba="0.5 0.5 0.0 1.0"/>
      </material>
    </visual>
    <visual>
      <geometry>
        <box size="0.36 0.24 0.24"/>
      </geometry>
      <origin xyz="-0.27 0.0 -0.12"/>
      <material name="translucent">
        <color rgba="0.5 0.5 0.5 1.0"/>
      </material>
    </visual>
  </link>
  <joint name="backRightAimingHip" type="revolute">
    <parent link="base_link"/>
    <child link="backRightHip"/>
    <axis xyz="0 0 1"/>
    <limit effort="1024" lower="-1.36135681656" upper="1.36135681656" velocity="0.5"/>
    <origin rpy="0 0 0" xyz="-0.36 0.0 0.27"/>
  </joint>
  <link name="backRightThigh">
    <visual>
      <geometry>
        <cylinder length="0.03" radius="0.09"/>
      </geometry>
      <origin rpy="1.57079632679 0 0" xyz="0.0 0.015 0.0"/>
      <material name="black">
        <color rgba="0.125 0.125 0.125 1.0"/>
      </material>
    </visual>
    <visual>
      <geometry>
        <box size="0.42 0.03 0.18"/>
      </geometry>
      <origin xyz="-0.18 0.045 0.0"/>
      <material name="mud">
        <color rgba="0.5 0.5 0.0 1.0"/>
      </material>
    </visual>
    <visual>
      <geometry>
        <box size="0.42 0.03 0.12"/>
      </geometry>
      <origin xyz="-0.18 -0.255 -0.03"/>
      <material name="mud">
        <color rgba="0.5 0.5 0.0 1.0"/>
      </material>
    </visual>
    <visual>
      <geometry>
        <cylinder length="0.03" radius="0.09"/>
      </geometry>
      <origin rpy="1.57079632679 0 0" xyz="-0.36 0.015 0.0"/>
      <material name="black">
        <color rgba="0.125 0.125 0.125 1.0"/>
      </material>
    </visual>
  </link>
  <joint name="backRightLiftingHip" type="revolute">
    <parent link="backRightHip"/>
    <child link="backRightThigh"/>
    <axis xyz="0 1 0"/>
    <limit effort="1024" lower="-2.18166156499" upper="2.18166156499" velocity="0.5"/>
    <origin xyz="-0.36 0.12 -0.12"/>
  </joint>
  <link name="backRightCalf">
    <visual>
      <geometry>
        <box size="0.36 0.24 0.24"/>
      </geometry>
      <origin xyz="-0.09 -0.12 0.0"/>
      <material name="translucent">
        <color rgba="0.5 0.5 0.5 1.0"/>
      </material>
    </visual>
  </link>
  <joint name="backRightKnee" type="revolute">
    <parent link="backRightThigh"/>
    <child link="backRightCalf"/>
    <axis xyz="0 -1 0"/>
    <limit effort="1024" lower="-2.26892802759" upper="2.26892802759" velocity="0.5"/>
    <origin xyz="-0.36 0 0"/>
  </joint>
  <link name="backRightFoot">
    <visual>
      <geometry>
        <cylinder length="0.03" radius="0.09"/>
      </geometry>
      <origin rpy="1.57079632679 0 0" xyz="0.0 0.135 0.0"/>
      <material name="mud">
        <color rgba="0.5 0.5 0.0 1.0"/>
      </material>
    </visual>
    <visual>
      <geometry>
        <cylinder length="0.03" radius="0.09"/>
      </geometry>
      <origin rpy="1.57079632679 0 0" xyz="0.0 -0.135 0.0"/>
      <material name="mud">
        <color rgba="0.5 0.5 0.0 1.0"/>
      </material>
    </visual>
  </link>
  <joint name="backRightAnkle" type="fixed">
    <parent link="backRightCalf"/>
    <child link="backRightFoot"/>
    <origin xyz="-0.24 -0.12 0"/>
  </joint>
  <link name="backLeftHip">
    <visual>
      <geometry>
        <cylinder length="0.03" radius="0.09"/>
      </geometry>
      <origin xyz="0.0 0.0 0.015"/>
      <material name="black">
        <color rgba="0.125 0.125 0.125 1.0"/>
      </material>
    </visual>
    <visual>
      <geometry>
        <box size="0.42 0.18 0.03"/>
      </geometry>
      <origin xyz="-0.18 0.0 0.045"/>
      <material name="mud">
        <color rgba="0.5 0.5 0.0 1.0"/>
      </material>
    </visual>
    <visual>
      <geometry>
        <box size="0.3 0.18 0.03"/>
      </geometry>
      <origin xyz="-0.24 0.0 0.015"/>
      <material name="mud">
        <color rgba="0.5 0.5 0.0 1.0"/>
      </material>
    </visual>
    <visual>
      <geometry>
        <box size="0.42 0.06 0.03"/>
      </geometry>
      <origin xyz="-0.18 0.0 -0.255"/>
      <material name="mud">
        <color rgba="0.5 0.5 0.0 1.0"/>
      </material>
    </visual>
    <visual>
      <geometry>
        <box size="0.36 0.24 0.24"/>
      </geometry>
      <origin xyz="-0.27 0.0 -0.12"/>
      <material name="translucent">
        <color rgba="0.5 0.5 0.5 1.0"/>
      </material>
    </visual>
  </link>
  <joint name="backLeftAimingHip" type="revolute">
    <parent link="base_link"/>
    <child link="backLeftHip"/>
    <axis xyz="0 0 1"/>
    <limit effort="1024" lower="-1.36135681656" upper="1.36135681656" velocity="0.5"/>
    <origin rpy="0 0 -1.57079632679" xyz="0.0 0.36 0.27"/>
  </joint>
  <link name="backLeftThigh">
    <visual>
      <geometry>
        <cylinder length="0.03" radius="0.09"/>
      </geometry>
      <origin rpy="1.57079632679 0 0" xyz="0.0 -0.015 0.0"/>
      <material name="black">
        <color rgba="0.125 0.125 0.125 1.0"/>
      </material>
    </visual>
    <visual>
      <geometry>
        <box size="0.42 0.03 0.18"/>
      </geometry>
      <origin xyz="-0.18 -0.045 0.0"/>
      <material name="mud">
        <color rgba="0.5 0.5 0.0 1.0"/>
      </material>
    </visual>
    <visual>
      <geometry>
        <box size="0.42 0.03 0.12"/>
      </geometry>
      <origin xyz="-0.18 0.255 -0.03"/>
      <material name="mud">
        <color rgba="0.5 0.5 0.0 1.0"/>
      </material>
    </visual>
    <visual>
      <geometry>
        <cylinder length="0.03" radius="0.09"/>
      </geometry>
      <origin rpy="1.57079632679 0 0" xyz="-0.36 -0.015 0.0"/>
      <material name="black">
        <color rgba="0.125 0.125 0.125 1.0"/>
      </material>
    </visual>
  </link>
  <joint name="backLeftLiftingHip" type="revolute">
    <parent link="backLeftHip"/>
    <child link="backLeftThigh"/>
    <axis xyz="0 -1 0"/>
    <limit effort="1024" lower="-2.18166156499" upper="2.18166156499" velocity="0.5"/>
    <origin xyz="-0.36 -0.12 -0.12"/>
  </joint>
  <link name="backLeftCalf">
    <visual>
      <geometry>
        <box size="0.36 0.24 0.24"/>
      </geometry>
      <origin xyz="-0.09 0.12 0.0"/>
      <material name="translucent">
        <color rgba="0.5 0.5 0.5 1.0"/>
      </material>
    </visual>
  </link>
  <joint name="backLeftKnee" type="revolute">
    <parent link="backLeftThigh"/>
    <child link="backLeftCalf"/>
    <axis xyz="0 1 0"/>
    <limit effort="1024" lower="-2.26892802759" upper="2.26892802759" velocity="0.5"/>
    <origin xyz="-0.36 0 0"/>
  </joint>
  <link name="backLeftFoot">
    <visual>
      <geometry>
        <cylinder length="0.03" radius="0.09"/>
      </geometry>
      <origin rpy="1.57079632679 0 0" xyz="0.0 0.135 0.0"/>
      <material name="mud">
        <color rgba="0.5 0.5 0.0 1.0"/>
      </material>
    </visual>
    <visual>
      <geometry>
        <cylinder length="0.03" radius="0.09"/>
      </geometry>
      <origin rpy="1.57079632679 0 0" xyz="0.0 -0.135 0.0"/>
      <material name="mud">
        <color rgba="0.5 0.5 0.0 1.0"/>
      </material>
    </visual>
  </link>
  <joint name="backLeftAnkle" type="fixed">
    <parent link="backLeftCalf"/>
    <child link="backLeftFoot"/>
    <origin xyz="-0.24 0.12 0"/>
  </joint>
  <link name="frontRightHip">
    <visual>
      <geometry>
        <cylinder length="0.03" radius="0.09"/>
      </geometry>
      <origin xyz="0.0 0.0 0.015"/>
      <material name="black">
        <color rgba="0.125 0.125 0.125 1.0"/>
      </material>
    </visual>
    <visual>
      <geometry>
        <box size="0.42 0.18 0.03"/>
      </geometry>
      <origin xyz="-0.18 0.0 0.045"/>
      <material name="mud">
        <color rgba="0.5 0.5 0.0 1.0"/>
      </material>
    </visual>
    <visual>
      <geometry>
        <box size="0.3 0.18 0.03"/>
      </geometry>
      <origin xyz="-0.24 0.0 0.015"/>
      <material name="mud">
        <color rgba="0.5 0.5 0.0 1.0"/>
      </material>
    </visual>
    <visual>
      <geometry>
        <box size="0.42 0.06 0.03"/>
      </geometry>
      <origin xyz="-0.18 0.0 -0.255"/>
      <material name="mud">
        <color rgba="0.5 0.5 0.0 1.0"/>
      </material>
    </visual>
    <visual>
      <geometry>
        <box size="0.36 0.24 0.24"/>
      </geometry>
      <origin xyz="-0.27 0.0 -0.12"/>
      <material name="translucent">
        <color rgba="0.5 0.5 0.5 1.0"/>
      </material>
    </visual>
  </link>
  <joint name="frontRightAimingHip" type="revolute">
    <parent link="base_link"/>
    <child link="frontRightHip"/>
    <axis xyz="0 0 1"/>
    <limit effort="1024" lower="-1.36135681656" upper="1.36135681656" velocity="0.5"/>
    <origin rpy="0 0 1.57079632679" xyz="0.0 -0.36 0.27"/>
  </joint>
  <link name="frontRightThigh">
    <visual>
      <geometry>
        <cylinder length="0.03" radius="0.09"/>
      </geometry>
      <origin rpy="1.57079632679 0 0" xyz="0.0 0.015 0.0"/>
      <material name="black">
        <color rgba="0.125 0.125 0.125 1.0"/>
      </material>
    </visual>
    <visual>
      <geometry>
        <box size="0.42 0.03 0.18"/>
      </geometry>
      <origin xyz="-0.18 0.045 0.0"/>
      <material name="mud">
        <color rgba="0.5 0.5 0.0 1.0"/>
      </material>
    </visual>
    <visual>
      <geometry>
        <box size="0.42 0.03 0.12"/>
      </geometry>
      <origin xyz="-0.18 -0.255 -0.03"/>
      <material name="mud">
        <color rgba="0.5 0.5 0.0 1.0"/>
      </material>
    </visual>
    <visual>
      <geometry>
        <cylinder length="0.03" radius="0.09"/>
      </geometry>
      <origin rpy="1.57079632679 0 0" xyz="-0.36 0.015 0.0"/>
      <material name="black">
        <color rgba="0.125 0.125 0.125 1.0"/>
      </material>
    </visual>
  </link>
  <joint name="frontRightLiftingHip" type="revolute">
    <parent link="frontRightHip"/>
    <child link="frontRightThigh"/>
    <axis xyz="0 1 0"/>
    <limit effort="1024" lower="-2.18166156499" upper="2.18166156499" velocity="0.5"/>
    <origin xyz="-0.36 0.12 -0.12"/>
  </joint>
  <link name="frontRightCalf">
    <visual>
      <geometry>
        <box size="0.36 0.24 0.24"/>
      </geometry>
      <origin xyz="-0.09 -0.12 0.0"/>
      <material name="translucent">
        <color rgba="0.5 0.5 0.5 1.0"/>
      </material>
    </visual>
  </link>
  <joint name="frontRightKnee" type="revolute">
    <parent link="frontRightThigh"/>
    <child link="frontRightCalf"/>
    <axis xyz="0 -1 0"/>
    <limit effort="1024" lower="-2.26892802759" upper="2.26892802759" velocity="0.5"/>
    <origin xyz="-0.36 0 0"/>
  </joint>
  <link name="frontRightFoot">
    <visual>
      <geometry>
        <cylinder length="0.03" radius="0.09"/>
      </geometry>
      <origin rpy="1.57079632679 0 0" xyz="0.0 0.135 0.0"/>
      <material name="mud">
        <color rgba="0.5 0.5 0.0 1.0"/>
      </material>
    </visual>
    <visual>
      <geometry>
        <cylinder length="0.03" radius="0.09"/>
      </geometry>
      <origin rpy="1.57079632679 0 0" xyz="0.0 -0.135 0.0"/>
      <material name="mud">
        <color rgba="0.5 0.5 0.0 1.0"/>
      </material>
    </visual>
  </link>
  <joint name="frontRightAnkle" type="fixed">
    <parent link="frontRightCalf"/>
    <child link="frontRightFoot"/>
    <origin xyz="-0.24 -0.12 0"/>
  </joint>
  <link name="frontLeftHip">
    <visual>
      <geometry>
        <cylinder length="0.03" radius="0.09"/>
      </geometry>
      <origin xyz="0.0 0.0 0.015"/>
      <material name="black">
        <color rgba="0.125 0.125 0.125 1.0"/>
      </material>
    </visual>
    <visual>
      <geometry>
        <box size="0.42 0.18 0.03"/>
      </geometry>
      <origin xyz="-0.18 0.0 0.045"/>
      <material name="mud">
        <color rgba="0.5 0.5 0.0 1.0"/>
      </material>
    </visual>
    <visual>
      <geometry>
        <box size="0.3 0.18 0.03"/>
      </geometry>
      <origin xyz="-0.24 0.0 0.015"/>
      <material name="mud">
        <color rgba="0.5 0.5 0.0 1.0"/>
      </material>
    </visual>
    <visual>
      <geometry>
        <box size="0.42 0.06 0.03"/>
      </geometry>
      <origin xyz="-0.18 0.0 -0.255"/>
      <material name="mud">
        <color rgba="0.5 0.5 0.0 1.0"/>
      </material>
    </visual>
    <visual>
      <geometry>
        <box size="0.36 0.24 0.24"/>
      </geometry>
      <origin xyz="-0.27 0.0 -0.12"/>
      <material name="translucent">
        <color rgba="0.5 0.5 0.5 1.0"/>
      </material>
    </visual>
  </link>
  <joint name="frontLeftAimingHip" type="revolute">
    <parent link="base_link"/>
    <child link="frontLeftHip"/>
    <axis xyz="0 0 1"/>
    <limit effort="1024" lower="-1.36135681656" upper="1.36135681656" velocity="0.5"/>
    <origin rpy="0 0 3.14159265359" xyz="0.36 0.0 0.27"/>
  </joint>
  <link name="frontLeftThigh">
    <visual>
      <geometry>
        <cylinder length="0.03" radius="0.09"/>
      </geometry>
      <origin rpy="1.57079632679 0 0" xyz="0.0 -0.015 0.0"/>
      <material name="black">
        <color rgba="0.125 0.125 0.125 1.0"/>
      </material>
    </visual>
    <visual>
      <geometry>
        <box size="0.42 0.03 0.18"/>
      </geometry>
      <origin xyz="-0.18 -0.045 0.0"/>
      <material name="mud">
        <color rgba="0.5 0.5 0.0 1.0"/>
      </material>
    </visual>
    <visual>
      <geometry>
        <box size="0.42 0.03 0.12"/>
      </geometry>
      <origin xyz="-0.18 0.255 -0.03"/>
      <material name="mud">
        <color rgba="0.5 0.5 0.0 1.0"/>
      </material>
    </visual>
    <visual>
      <geometry>
        <cylinder length="0.03" radius="0.09"/>
      </geometry>
      <origin rpy="1.57079632679 0 0" xyz="-0.36 -0.015 0.0"/>
      <material name="black">
        <color rgba="0.125 0.125 0.125 1.0"/>
      </material>
    </visual>
  </link>
  <joint name="frontLeftLiftingHip" type="revolute">
    <parent link="frontLeftHip"/>
    <child link="frontLeftThigh"/>
    <axis xyz="0 -1 0"/>
    <limit effort="1024" lower="-2.18166156499" upper="2.18166156499" velocity="0.5"/>
    <origin xyz="-0.36 -0.12 -0.12"/>
  </joint>
  <link name="frontLeftCalf">
    <visual>
      <geometry>
        <box size="0.36 0.24 0.24"/>
      </geometry>
      <origin xyz="-0.09 0.12 0.0"/>
      <material name="translucent">
        <color rgba="0.5 0.5 0.5 1.0"/>
      </material>
    </visual>
  </link>
  <joint name="frontLeftKnee" type="revolute">
    <parent link="frontLeftThigh"/>
    <child link="frontLeftCalf"/>
    <axis xyz="0 1 0"/>
    <limit effort="1024" lower="-2.26892802759" upper="2.26892802759" velocity="0.5"/>
    <origin xyz="-0.36 0 0"/>
  </joint>
  <link name="frontLeftFoot">
    <visual>
      <geometry>
        <cylinder length="0.03" radius="0.09"/>
      </geometry>
      <origin rpy="1.57079632679 0 0" xyz="0.0 0.135 0.0"/>
      <material name="mud">
        <color rgba="0.5 0.5 0.0 1.0"/>
      </material>
    </visual>
    <visual>
      <geometry>
        <cylinder length="0.03" radius="0.09"/>
      </geometry>
      <origin rpy="1.57079632679 0 0" xyz="0.0 -0.135 0.0"/>
      <material name="mud">
        <color rgba="0.5 0.5 0.0 1.0"/>
      </material>
    </visual>
  </link>
  <joint name="frontLeftAnkle" type="fixed">
    <parent link="frontLeftCalf"/>
    <child link="frontLeftFoot"/>
    <origin xyz="-0.24 0.12 0"/>
  </joint>
</robot>

