<?xml version="1.0" ?>
<!-- =================================================================================== -->
<!-- |    This document was autogenerated by xacro from Prototype.urdf.xacro           | -->
<!-- |    EDITING THIS FILE BY HAND IS NOT RECOMMENDED                                 | -->
<!-- =================================================================================== -->
<!-- +X is forward, +Y is left, +Z is up -->
<robot name="Prototype" xmlns:xacro="http://www.ros.org/wiki/xacro">
  <material name="white">
    <color rgba="0.875 0.875 0.875 1.0"/>
  </material>
  <material name="yellow">
    <color rgba="0.875 0.875 0.125 1.0"/>
  </material>
  <material name="black">
    <color rgba="0.125 0.125 0.125 1.0"/>
  </material>
  <material name="blue">
    <color rgba="0.125 0.125 1.0 1.0"/>
  </material>
  <link name="base_link">
    <visual>
      <geometry>
        <box size="0.09 1.14 0.02"/>
      </geometry>
      <origin rpy="0 0 0.0" xyz="0.303108891325 0.0 0.01"/>
      <material name="yellow"/>
    </visual>
    <visual>
      <geometry>
        <box size="0.09 1.14 0.02"/>
      </geometry>
      <origin rpy="0 0 2.09439510239" xyz="-0.151554445662 0.2625 0.01"/>
      <material name="yellow"/>
    </visual>
    <visual>
      <geometry>
        <box size="0.09 1.14 0.02"/>
      </geometry>
      <origin rpy="0 0 -2.09439510239" xyz="-0.151554445662 -0.2625 0.01"/>
      <material name="yellow"/>
    </visual>
  </link>
  <link name="back_hip">
    <!-- unless adjusted, servo horn aims along +X, and large portion of horn extends toward +Z -->
    <visual>
      <geometry>
        <cylinder length="0.03" radius="0.035"/>
      </geometry>
      <origin rpy="0 1.57079632679 0" xyz="-0.035 0 0"/>
      <material name="black"/>
    </visual>
    <visual>
      <geometry>
        <box size="0.02 0.12 0.04"/>
      </geometry>
      <origin xyz="-0.01 0 0"/>
      <material name="black"/>
    </visual>
    <visual>
      <geometry>
        <box size="0.02 0.05 0.17"/>
      </geometry>
      <origin xyz="-0.01 0 0.105"/>
      <material name="black"/>
    </visual>
    <visual>
      <geometry>
        <box size="0.02 0.05 0.15"/>
      </geometry>
      <origin xyz="-0.01 0 -0.095"/>
      <material name="black"/>
    </visual>
  </link>
  <!-- unless adjusted, servo aims along +X, servo origin is at the joint, and larger width portion extends toward +Y -->
  <link name="back_aiming_hip_servo">
    <visual>
      <geometry>
        <box size="0.22 0.22 0.12"/>
      </geometry>
      <origin xyz="-0.21 0.05 0"/>
      <material name="blue"/>
    </visual>
    <visual>
      <geometry>
        <cylinder length="0.05" radius="0.06"/>
      </geometry>
      <origin rpy="0 1.57079632679 0" xyz="-0.075 0 0"/>
      <material name="blue"/>
    </visual>
  </link>
  <joint name="back_aiming_hip_servo" type="fixed">
    <parent link="base_link"/>
    <child link="back_aiming_hip_servo"/>
    <origin rpy="0.0 0.0 3.14159265359" xyz="-0.75 0 -0.06"/>
  </joint>
  <joint name="back_aiming_hip" type="revolute">
    <parent link="base_link"/>
    <child link="back_hip"/>
    <axis xyz="1.0 0.0 0.0"/>
    <limit effort="1024.0" lower="-1.57079632679" upper="1.57079632679" velocity="0.5"/>
    <origin rpy="0.0 0.0 3.14159265359" xyz="-0.75 0 -0.06"/>
  </joint>
  <link name="back_thigh">
    <visual>
      <geometry>
        <cylinder length="0.94" radius="0.04"/>
      </geometry>
      <origin xyz="0.04 0 0.3"/>
      <material name="yellow"/>
    </visual>
    <!-- unless adjusted, servo horn aims along +X, and large portion of horn extends toward +Z -->
    <visual>
      <geometry>
        <cylinder length="0.03" radius="0.035"/>
      </geometry>
      <origin rpy="0 1.57079632679 0" xyz="-0.035 0 0"/>
      <material name="black"/>
    </visual>
    <visual>
      <geometry>
        <box size="0.02 0.12 0.04"/>
      </geometry>
      <origin xyz="-0.01 0 0"/>
      <material name="black"/>
    </visual>
    <visual>
      <geometry>
        <box size="0.02 0.05 0.17"/>
      </geometry>
      <origin xyz="-0.01 0 0.105"/>
      <material name="black"/>
    </visual>
    <visual>
      <geometry>
        <box size="0.02 0.05 0.15"/>
      </geometry>
      <origin xyz="-0.01 0 -0.095"/>
      <material name="black"/>
    </visual>
  </link>
  <!-- unless adjusted, servo aims along +X, servo origin is at the joint, and larger width portion extends toward +Y -->
  <link name="back_lifting_hip_servo">
    <visual>
      <geometry>
        <box size="0.22 0.22 0.12"/>
      </geometry>
      <origin xyz="-0.21 0.05 0"/>
      <material name="blue"/>
    </visual>
    <visual>
      <geometry>
        <cylinder length="0.05" radius="0.06"/>
      </geometry>
      <origin rpy="0 1.57079632679 0" xyz="-0.075 0 0"/>
      <material name="blue"/>
    </visual>
  </link>
  <joint name="back_lifting_hip_servo" type="fixed">
    <parent link="back_hip"/>
    <child link="back_lifting_hip_servo"/>
    <origin rpy="-1.57079632679 0.0 -1.57079632679" xyz="0.07 -0.21 0"/>
  </joint>
  <joint name="back_lifting_hip" type="revolute">
    <parent link="back_hip"/>
    <child link="back_thigh"/>
    <axis xyz="1.0 0.0 -0.0"/>
    <limit effort="1024.0" lower="-1.57079632679" upper="1.57079632679" velocity="0.5"/>
    <origin rpy="-1.57079632679 0.0 -1.57079632679" xyz="0.07 -0.21 0"/>
  </joint>
  <link name="back_calf">
    <visual>
      <geometry>
        <cylinder length="0.93" radius="0.04"/>
      </geometry>
      <origin xyz="0.04 0 0.295"/>
      <material name="yellow"/>
    </visual>
    <!-- unless adjusted, servo horn aims along +X, and large portion of horn extends toward +Z -->
    <visual>
      <geometry>
        <cylinder length="0.03" radius="0.035"/>
      </geometry>
      <origin rpy="0 1.57079632679 0" xyz="-0.035 0 0"/>
      <material name="black"/>
    </visual>
    <visual>
      <geometry>
        <box size="0.02 0.12 0.04"/>
      </geometry>
      <origin xyz="-0.01 0 0"/>
      <material name="black"/>
    </visual>
    <visual>
      <geometry>
        <box size="0.02 0.05 0.17"/>
      </geometry>
      <origin xyz="-0.01 0 0.105"/>
      <material name="black"/>
    </visual>
    <visual>
      <geometry>
        <box size="0.02 0.05 0.15"/>
      </geometry>
      <origin xyz="-0.01 0 -0.095"/>
      <material name="black"/>
    </visual>
  </link>
  <!-- unless adjusted, servo aims along +X, servo origin is at the joint, and larger width portion extends toward +Y -->
  <link name="back_knee_servo">
    <visual>
      <geometry>
        <box size="0.22 0.22 0.12"/>
      </geometry>
      <origin xyz="-0.21 0.05 0"/>
      <material name="blue"/>
    </visual>
    <visual>
      <geometry>
        <cylinder length="0.05" radius="0.06"/>
      </geometry>
      <origin rpy="0 1.57079632679 0" xyz="-0.075 0 0"/>
      <material name="blue"/>
    </visual>
  </link>
  <joint name="back_knee_servo" type="fixed">
    <parent link="back_thigh"/>
    <child link="back_knee_servo"/>
    <origin rpy="1.57079632679 0.0 3.14159265359" xyz="-0.31 0 0.66"/>
  </joint>
  <joint name="back_knee" type="revolute">
    <parent link="back_thigh"/>
    <child link="back_calf"/>
    <axis xyz="1.0 0.0 0.0"/>
    <limit effort="1024.0" lower="-1.57079632679" upper="1.57079632679" velocity="0.5"/>
    <origin rpy="1.57079632679 0.0 3.14159265359" xyz="-0.31 0 0.66"/>
  </joint>
  <link name="back_foot"/>
  <joint name="back_joint" type="fixed">
    <parent link="back_calf"/>
    <child link="back_foot"/>
    <origin xyz="0.04 0 0.76"/>
  </joint>
  <link name="left_hip">
    <!-- unless adjusted, servo horn aims along +X, and large portion of horn extends toward +Z -->
    <visual>
      <geometry>
        <cylinder length="0.03" radius="0.035"/>
      </geometry>
      <origin rpy="0 1.57079632679 0" xyz="-0.035 0 0"/>
      <material name="black"/>
    </visual>
    <visual>
      <geometry>
        <box size="0.02 0.12 0.04"/>
      </geometry>
      <origin xyz="-0.01 0 0"/>
      <material name="black"/>
    </visual>
    <visual>
      <geometry>
        <box size="0.02 0.05 0.17"/>
      </geometry>
      <origin xyz="-0.01 0 0.105"/>
      <material name="black"/>
    </visual>
    <visual>
      <geometry>
        <box size="0.02 0.05 0.15"/>
      </geometry>
      <origin xyz="-0.01 0 -0.095"/>
      <material name="black"/>
    </visual>
  </link>
  <!-- unless adjusted, servo aims along +X, servo origin is at the joint, and larger width portion extends toward +Y -->
  <link name="left_aiming_hip_servo">
    <visual>
      <geometry>
        <box size="0.22 0.22 0.12"/>
      </geometry>
      <origin xyz="-0.21 0.05 0"/>
      <material name="blue"/>
    </visual>
    <visual>
      <geometry>
        <cylinder length="0.05" radius="0.06"/>
      </geometry>
      <origin rpy="0 1.57079632679 0" xyz="-0.075 0 0"/>
      <material name="blue"/>
    </visual>
  </link>
  <joint name="left_aiming_hip_servo" type="fixed">
    <parent link="base_link"/>
    <child link="left_aiming_hip_servo"/>
    <origin rpy="0.0 0.0 1.57079632679" xyz="0.3125 0.67 -0.06"/>
  </joint>
  <joint name="left_aiming_hip" type="revolute">
    <parent link="base_link"/>
    <child link="left_hip"/>
    <axis xyz="1.0 0.0 0.0"/>
    <limit effort="1024.0" lower="-1.57079632679" upper="1.57079632679" velocity="0.5"/>
    <origin rpy="0.0 0.0 1.57079632679" xyz="0.3125 0.67 -0.06"/>
  </joint>
  <link name="left_thigh">
    <visual>
      <geometry>
        <cylinder length="0.94" radius="0.04"/>
      </geometry>
      <origin xyz="0.04 0 0.3"/>
      <material name="yellow"/>
    </visual>
    <!-- unless adjusted, servo horn aims along +X, and large portion of horn extends toward +Z -->
    <visual>
      <geometry>
        <cylinder length="0.03" radius="0.035"/>
      </geometry>
      <origin rpy="0 1.57079632679 0" xyz="-0.035 0 0"/>
      <material name="black"/>
    </visual>
    <visual>
      <geometry>
        <box size="0.02 0.12 0.04"/>
      </geometry>
      <origin xyz="-0.01 0 0"/>
      <material name="black"/>
    </visual>
    <visual>
      <geometry>
        <box size="0.02 0.05 0.17"/>
      </geometry>
      <origin xyz="-0.01 0 0.105"/>
      <material name="black"/>
    </visual>
    <visual>
      <geometry>
        <box size="0.02 0.05 0.15"/>
      </geometry>
      <origin xyz="-0.01 0 -0.095"/>
      <material name="black"/>
    </visual>
  </link>
  <!-- unless adjusted, servo aims along +X, servo origin is at the joint, and larger width portion extends toward +Y -->
  <link name="left_lifting_hip_servo">
    <visual>
      <geometry>
        <box size="0.22 0.22 0.12"/>
      </geometry>
      <origin xyz="-0.21 0.05 0"/>
      <material name="blue"/>
    </visual>
    <visual>
      <geometry>
        <cylinder length="0.05" radius="0.06"/>
      </geometry>
      <origin rpy="0 1.57079632679 0" xyz="-0.075 0 0"/>
      <material name="blue"/>
    </visual>
  </link>
  <joint name="left_lifting_hip_servo" type="fixed">
    <parent link="left_hip"/>
    <child link="left_lifting_hip_servo"/>
    <origin rpy="-1.57079632679 0.0 -1.57079632679" xyz="0.07 -0.21 0"/>
  </joint>
  <joint name="left_lifting_hip" type="revolute">
    <parent link="left_hip"/>
    <child link="left_thigh"/>
    <axis xyz="1.0 0.0 -0.0"/>
    <limit effort="1024.0" lower="-1.57079632679" upper="1.57079632679" velocity="0.5"/>
    <origin rpy="-1.57079632679 0.0 -1.57079632679" xyz="0.07 -0.21 0"/>
  </joint>
  <link name="left_calf">
    <visual>
      <geometry>
        <cylinder length="0.93" radius="0.04"/>
      </geometry>
      <origin xyz="0.04 0 0.295"/>
      <material name="yellow"/>
    </visual>
    <!-- unless adjusted, servo horn aims along +X, and large portion of horn extends toward +Z -->
    <visual>
      <geometry>
        <cylinder length="0.03" radius="0.035"/>
      </geometry>
      <origin rpy="0 1.57079632679 0" xyz="-0.035 0 0"/>
      <material name="black"/>
    </visual>
    <visual>
      <geometry>
        <box size="0.02 0.12 0.04"/>
      </geometry>
      <origin xyz="-0.01 0 0"/>
      <material name="black"/>
    </visual>
    <visual>
      <geometry>
        <box size="0.02 0.05 0.17"/>
      </geometry>
      <origin xyz="-0.01 0 0.105"/>
      <material name="black"/>
    </visual>
    <visual>
      <geometry>
        <box size="0.02 0.05 0.15"/>
      </geometry>
      <origin xyz="-0.01 0 -0.095"/>
      <material name="black"/>
    </visual>
  </link>
  <!-- unless adjusted, servo aims along +X, servo origin is at the joint, and larger width portion extends toward +Y -->
  <link name="left_knee_servo">
    <visual>
      <geometry>
        <box size="0.22 0.22 0.12"/>
      </geometry>
      <origin xyz="-0.21 0.05 0"/>
      <material name="blue"/>
    </visual>
    <visual>
      <geometry>
        <cylinder length="0.05" radius="0.06"/>
      </geometry>
      <origin rpy="0 1.57079632679 0" xyz="-0.075 0 0"/>
      <material name="blue"/>
    </visual>
  </link>
  <joint name="left_knee_servo" type="fixed">
    <parent link="left_thigh"/>
    <child link="left_knee_servo"/>
    <origin rpy="1.57079632679 0.0 3.14159265359" xyz="-0.31 0 0.66"/>
  </joint>
  <joint name="left_knee" type="revolute">
    <parent link="left_thigh"/>
    <child link="left_calf"/>
    <axis xyz="1.0 0.0 0.0"/>
    <limit effort="1024.0" lower="-1.57079632679" upper="1.57079632679" velocity="0.5"/>
    <origin rpy="1.57079632679 0.0 3.14159265359" xyz="-0.31 0 0.66"/>
  </joint>
  <link name="left_foot"/>
  <joint name="left_joint" type="fixed">
    <parent link="left_calf"/>
    <child link="left_foot"/>
    <origin xyz="0.04 0 0.76"/>
  </joint>
  <link name="right_hip">
    <!-- unless adjusted, servo horn aims along +X, and large portion of horn extends toward +Z -->
    <visual>
      <geometry>
        <cylinder length="0.03" radius="0.035"/>
      </geometry>
      <origin rpy="0 1.57079632679 0" xyz="-0.035 0 0"/>
      <material name="black"/>
    </visual>
    <visual>
      <geometry>
        <box size="0.02 0.12 0.04"/>
      </geometry>
      <origin xyz="-0.01 0 0"/>
      <material name="black"/>
    </visual>
    <visual>
      <geometry>
        <box size="0.02 0.05 0.17"/>
      </geometry>
      <origin xyz="-0.01 0 0.105"/>
      <material name="black"/>
    </visual>
    <visual>
      <geometry>
        <box size="0.02 0.05 0.15"/>
      </geometry>
      <origin xyz="-0.01 0 -0.095"/>
      <material name="black"/>
    </visual>
  </link>
  <!-- unless adjusted, servo aims along +X, servo origin is at the joint, and larger width portion extends toward +Y -->
  <link name="right_aiming_hip_servo">
    <visual>
      <geometry>
        <box size="0.22 0.22 0.12"/>
      </geometry>
      <origin xyz="-0.21 0.05 0"/>
      <material name="blue"/>
    </visual>
    <visual>
      <geometry>
        <cylinder length="0.05" radius="0.06"/>
      </geometry>
      <origin rpy="0 1.57079632679 0" xyz="-0.075 0 0"/>
      <material name="blue"/>
    </visual>
  </link>
  <joint name="right_aiming_hip_servo" type="fixed">
    <parent link="base_link"/>
    <child link="right_aiming_hip_servo"/>
    <origin rpy="3.14159265359 0.0 -1.57079632679" xyz="0.3125 -0.67 -0.06"/>
  </joint>
  <joint name="right_aiming_hip" type="revolute">
    <parent link="base_link"/>
    <child link="right_hip"/>
    <axis xyz="1.0 -0.0 0.0"/>
    <limit effort="1024.0" lower="-1.57079632679" upper="1.57079632679" velocity="0.5"/>
    <origin rpy="6.28318530718 0.0 -1.57079632679" xyz="0.3125 -0.67 -0.06"/>
  </joint>
  <link name="right_thigh">
    <visual>
      <geometry>
        <cylinder length="0.94" radius="0.04"/>
      </geometry>
      <origin xyz="0.04 0 0.3"/>
      <material name="yellow"/>
    </visual>
    <!-- unless adjusted, servo horn aims along +X, and large portion of horn extends toward +Z -->
    <visual>
      <geometry>
        <cylinder length="0.03" radius="0.035"/>
      </geometry>
      <origin rpy="0 1.57079632679 0" xyz="-0.035 0 0"/>
      <material name="black"/>
    </visual>
    <visual>
      <geometry>
        <box size="0.02 0.12 0.04"/>
      </geometry>
      <origin xyz="-0.01 0 0"/>
      <material name="black"/>
    </visual>
    <visual>
      <geometry>
        <box size="0.02 0.05 0.17"/>
      </geometry>
      <origin xyz="-0.01 0 0.105"/>
      <material name="black"/>
    </visual>
    <visual>
      <geometry>
        <box size="0.02 0.05 0.15"/>
      </geometry>
      <origin xyz="-0.01 0 -0.095"/>
      <material name="black"/>
    </visual>
  </link>
  <!-- unless adjusted, servo aims along +X, servo origin is at the joint, and larger width portion extends toward +Y -->
  <link name="right_lifting_hip_servo">
    <visual>
      <geometry>
        <box size="0.22 0.22 0.12"/>
      </geometry>
      <origin xyz="-0.21 0.05 0"/>
      <material name="blue"/>
    </visual>
    <visual>
      <geometry>
        <cylinder length="0.05" radius="0.06"/>
      </geometry>
      <origin rpy="0 1.57079632679 0" xyz="-0.075 0 0"/>
      <material name="blue"/>
    </visual>
  </link>
  <joint name="right_lifting_hip_servo" type="fixed">
    <parent link="right_hip"/>
    <child link="right_lifting_hip_servo"/>
    <origin rpy="-1.57079632679 0.0 1.57079632679" xyz="0.07 0.21 0"/>
  </joint>
  <joint name="right_lifting_hip" type="revolute">
    <parent link="right_hip"/>
    <child link="right_thigh"/>
    <axis xyz="1.0 0.0 -0.0"/>
    <limit effort="1024.0" lower="-1.57079632679" upper="1.57079632679" velocity="0.5"/>
    <origin rpy="1.57079632679 0.0 1.57079632679" xyz="0.07 0.21 0"/>
  </joint>
  <link name="right_calf">
    <visual>
      <geometry>
        <cylinder length="0.93" radius="0.04"/>
      </geometry>
      <origin xyz="0.04 0 0.295"/>
      <material name="yellow"/>
    </visual>
    <!-- unless adjusted, servo horn aims along +X, and large portion of horn extends toward +Z -->
    <visual>
      <geometry>
        <cylinder length="0.03" radius="0.035"/>
      </geometry>
      <origin rpy="0 1.57079632679 0" xyz="-0.035 0 0"/>
      <material name="black"/>
    </visual>
    <visual>
      <geometry>
        <box size="0.02 0.12 0.04"/>
      </geometry>
      <origin xyz="-0.01 0 0"/>
      <material name="black"/>
    </visual>
    <visual>
      <geometry>
        <box size="0.02 0.05 0.17"/>
      </geometry>
      <origin xyz="-0.01 0 0.105"/>
      <material name="black"/>
    </visual>
    <visual>
      <geometry>
        <box size="0.02 0.05 0.15"/>
      </geometry>
      <origin xyz="-0.01 0 -0.095"/>
      <material name="black"/>
    </visual>
  </link>
  <!-- unless adjusted, servo aims along +X, servo origin is at the joint, and larger width portion extends toward +Y -->
  <link name="right_knee_servo">
    <visual>
      <geometry>
        <box size="0.22 0.22 0.12"/>
      </geometry>
      <origin xyz="-0.21 0.05 0"/>
      <material name="blue"/>
    </visual>
    <visual>
      <geometry>
        <cylinder length="0.05" radius="0.06"/>
      </geometry>
      <origin rpy="0 1.57079632679 0" xyz="-0.075 0 0"/>
      <material name="blue"/>
    </visual>
  </link>
  <joint name="right_knee_servo" type="fixed">
    <parent link="right_thigh"/>
    <child link="right_knee_servo"/>
    <origin rpy="1.57079632679 0.0 3.14159265359" xyz="-0.31 0 0.66"/>
  </joint>
  <joint name="right_knee" type="revolute">
    <parent link="right_thigh"/>
    <child link="right_calf"/>
    <axis xyz="1.0 0.0 0.0"/>
    <limit effort="1024.0" lower="-1.57079632679" upper="1.57079632679" velocity="0.5"/>
    <origin rpy="4.71238898038 0.0 3.14159265359" xyz="-0.31 0 0.66"/>
  </joint>
  <link name="right_foot"/>
  <joint name="right_joint" type="fixed">
    <parent link="right_calf"/>
    <child link="right_foot"/>
    <origin xyz="0.04 0 0.76"/>
  </joint>
</robot>

